Workbook
Name Slicer_Month_Name: #N/A
Name Slicer_Sales_Channel: #N/A

Sheet Raw Data
A1: Order ID | B1: Order Date | C1: Order Time | D1: Customer Name | E1: Email | F1: Phone | G1: City | H1: State | I1: Country | J1: Line Items | K1: Primary Category | L1: Total Items | M1: Subtotal ($) | N1: Discount Code | O1: Discount Amount ($) | P1: Shipping ($) | Q1: Tax ($) | R1: Order Total ($) | S1: Payment Method | T1: Sales Channel | U1: Fulfillment Status | V1: Fulfillment Date | W1: Refund Amount ($)
A2: #ORD-10001 | B2: 2024-02-24 | C2: 04:35:15 | D2: Mason Johnson | E2: mason.johnson36@gmail.com | F2: +1-933-765-9928 | G2: Portland | H2: OR | I2: United States | J2: Anti-Aging Serum 1oz x1 | Men's Grooming Kit x1 | Leather Wallet Slim x1 | K2: Beauty | L2: 3 | M2: 115.97 | N2: None | O2: 0 | P2: 0 | Q2: 8.12 | R2: 124.09 | S2: Credit Card | T2: Facebook | U2: Refunded | V2: 2024-02-26 | W2: 124.09
A3: #ORD-10002 | B3: 2024-12-03 | C3: 14:27:58 | D3: Sofia Anderson | E3: sofia.anderson76@gmail.com | F3: +1-294-489-2584 | G3: Charlotte | H3: NC | I3: United States | J3: High-Waist Leggings x1 | K3: Apparel | L3: 1 | M3: 42.99 | N3: WELCOME15 | O3: 6.45 | P3: 7.99 | Q3: 2.92 | R3: 47.45 | S3: Credit Card | T3: TikTok Shop | U3: Partially Fulfilled | V3: 2024-12-04 | W3: 0
A4: #ORD-10003 | B4: 2024-07-27 | C4: 06:00:29 | D4: Emily Thompson | E4: emily.thompson34@outlook.com | F4: +1-246-777-4733 | G4: Nashville | H4: TN | I4: United States | J4: Bamboo Sunglasses x1 | K4: Bags & Accessories | L4: 1 | M4: 24.99 | N4: FLASH25 | O4: 6.25 | P4: 7.99 | Q4: 1.87 | R4: 28.6 | S4: PayPal | T4: Direct | U4: Fulfilled | V4: 2024-07-28 | W4: 0
A5: #ORD-10004 | B5: 2024-06-25 | C5: 02:05:25 | D5: Evelyn Garcia | E5: evelyn.garcia30@yahoo.com | F5: +1-946-350-3677 | G5: Milwaukee | H5: WI | I5: United States | J5: Insulated Water Bottle 32oz x1 | Running Shoes - Men's x1 | K5: Sports & Fitness | L5: 2 | M5: 102.98 | N5: SAVE10 | O5: 10.3 | P5: 0 | Q5: 9.27 | R5: 101.95 | S5: Google Pay | T5: Facebook | U5: Fulfilled | V5: 2024-06-30 | W5: 0
A6: #ORD-10005 | B6: 2024-05-05 | C6: 22:32:02 | D6: Sebastian Harris | E6: sebastian.harris82@yahoo.com | F6: +1-871-611-7482 | G6: Dallas | H6: TX | I6: United States | J6: Classic Fit Polo Shirt x2 | Portable Bluetooth Speaker x2 | Casual Sneakers x1 | K6: Apparel | L6: 3 | M6: 229.95 | N6: None | O6: 0 | P6: 0 | Q6: 16.1 | R6: 246.05 | S6: Google Pay | T6: Facebook | U6: Partially Fulfilled | V6: 2024-05-07 | W6: 0
A7: #ORD-10006 | B7: 2024-08-06 | C7: 00:19:48 | D7: Sebastian Martinez | E7: sebastian.martinez18@gmail.com | F7: +1-293-873-1771 | G7: Dallas | H7: TX | I7: United States | J7: Men's Grooming Kit x1 | Linen Throw Blanket x1 | K7: Beauty | L7: 2 | M7: 75.98 | N7: SAVE10 | O7: 7.6 | P7: 0 | Q7: 4.79 | R7: 73.17 | S7: Afterpay | T7: Online Store | U7: Cancelled | W7: 0
A8: #ORD-10007 | B8: 2024-01-25 | C8: 16:07:16 | D8: Mason Martinez | E8: mason.martinez21@yahoo.com | F8: +1-968-373-6573 | G8: Oklahoma City | H8: OK | I8: United States | J8: Scented Soy Candle Set x3 | K8: Home & Living | L8: 1 | M8: 68.97 | N8: FLASH25 | O8: 17.24 | P8: 7.99 | Q8: 4.66 | R8: 64.38 | S8: Apple Pay | T8: Online Store | U8: Fulfilled | V8: 2024-01-30 | W8: 0
A9: #ORD-10008 | B9: 2024-10-07 | C9: 10:23:08 | D9: Mason Jackson | E9: mason.jackson21@gmail.com | F9: +1-752-897-9689 | G9: Columbus | H9: OH | I9: United States | J9: Hiking Boots x1 | Air Fryer 5.8Qt x2 | Classic Fit Polo Shirt x2 | K9: Footwear | L9: 3 | M9: 339.95 | N9: SAVE10 | O9: 33.99 | P9: 0 | Q9: 30.6 | R9: 336.56 | S9: Debit Card | T9: Online Store | U9: Partially Fulfilled | V9: 2024-10-09 | W9: 0
A10: #ORD-10009 | B10: 2024-12-26 | C10: 19:49:36 | D10: Emma Flores | E10: emma.flores63@gmail.com | F10: +1-949-597-2133 | G10: Austin | H10: TX | I10: United States | J10: Denim Jacket x2 | K10: Apparel | L10: 1 | M10: 129.98 | N10: None | O10: 0 | P10: 0 | Q10: 7.8 | R10: 137.78 | S10: Credit Card | T10: Facebook | U10: Fulfilled | V10: 2024-12-27 | W10: 0
A11: #ORD-10010 | B11: 2024-08-01 | C11: 12:32:27 | D11: Grace Rodriguez | E11: grace.rodriguez85@gmail.com | F11: +1-608-787-7118 | G11: Phoenix | H11: AZ | I11: United States | J11: Air Fryer 5.8Qt x2 | K11: Kitchen | L11: 1 | M11: 159.98 | N11: WELCOME15 | O11: 24 | P11: 0 | Q11: 9.52 | R11: 145.5 | S11: Google Pay | T11: Google Shopping | U11: Fulfilled | V11: 2024-08-04 | W11: 0
A12: #ORD-10011 | B12: 2024-01-25 | C12: 20:45:52 | D12: Avery Wright | E12: avery.wright16@gmail.com | F12: +1-232-980-6413 | G12: Charlotte | H12: NC | I12: United States | J12: Linen Throw Blanket x1 | K12: Home & Living | L12: 1 | M12: 39.99 | N12: LOYALTY5 | O12: 2 | P12: 5.99 | Q12: 2.28 | R12: 46.26 | S12: Credit Card | T12: Facebook | U12: Fulfilled | V12: 2024-01-26 | W12: 0
A13: #ORD-10012 | B13: 2024-02-21 | C13: 09:14:08 | D13: Ava King | E13: ava.king36@yahoo.com | F13: +1-620-578-1887 | G13: San Diego | H13: CA | I13: United States | J13: Leather Wallet Slim x1 | Linen Throw Blanket x1 | K13: Bags & Accessories | L13: 2 | M13: 69.98 | N13: SUMMER20 | O13: 14 | P13: 9.99 | Q13: 3.92 | R13: 69.89 | S13: Credit Card | T13: Facebook | U13: Partially Fulfilled | V13: 2024-02-25 | W13: 0
A14: #ORD-10013 | B14: 2024-11-30 | C14: 15:22:12 | D14: Sophia Brown | E14: sophia.brown94@gmail.com | F14: +1-763-200-1828 | G14: Fort Worth | H14: TX | I14: United States | J14: Running Shoes - Women's x1 | K14: Footwear | L14: 1 | M14: 69.99 | N14: SUMMER20 | O14: 14 | P14: 5.99 | Q14: 4.76 | R14: 66.74 | S14: Credit Card | T14: Instagram | U14: Fulfilled | V14: 2024-12-04 | W14: 0
A15: #ORD-10014 | B15: 2024-07-07 | C15: 14:30:12 | D15: Grace Smith | E15: grace.smith97@yahoo.com | F15: +1-492-533-8973 | G15: Chicago | H15: IL | I15: United States | J15: Canvas Backpack 25L x2 | Protein Powder Chocolate 2lb x1 | K15: Bags & Accessories | L15: 2 | M15: 154.97 | N15: None | O15: 0 | P15: 0 | Q15: 13.17 | R15: 168.14 | S15: Credit Card | T15: Email Campaign | U15: Cancelled | W15: 0
A16: #ORD-10015 | B16: 2024-07-29 | C16: 13:37:32 | D16: James Gonzalez | E16: james.gonzalez28@outlook.com | F16: +1-282-971-4044 | G16: San Jose | H16: CA | I16: United States | J16: Resistance Band Set x1 | K16: Sports & Fitness | L16: 1 | M16: 24.99 | N16: LOYALTY5 | O16: 1.25 | P16: 9.99 | Q16: 2.14 | R16: 35.87 | S16: Google Pay | T16: Instagram | U16: Fulfilled | V16: 2024-08-03 | W16: 0
A17: #ORD-10016 | B17: 2024-12-31 | C17: 16:18:43 | D17: Ava Flores | E17: ava.flores87@yahoo.com | F17: +1-334-787-5915 | G17: Chicago | H17: IL | I17: United States | J17: Casual Sneakers x1 | Linen Throw Blanket x1 | Scented Soy Candle Set x1 | Portable Bluetooth Speaker x1 | K17: Footwear | L17: 4 | M17: 172.96 | N17: SAVE10 | O17: 17.3 | P17: 0 | Q17: 10.9 | R17: 166.56 | S17: PayPal | T17: Online Store | U17: Fulfilled | V17: 2025-01-04 | W17: 0
A18: #ORD-10017 | B18: 2024-08-29 | C18: 05:37:25 | D18: Sebastian Lee | E18: sebastian.lee97@yahoo.com | F18: +1-883-936-5905 | G18: Tucson | H18: AZ | I18: United States | J18: Smart LED Desk Lamp x1 | USB-C Fast Charger 65W x3 | Coffee Maker Programmable x2 | Running Shoes - Women's x2 | Air Fryer 5.8Qt x1 | K18: Electronics | L18: 5 | M18: 459.91 | N18: None | O18: 0 | P18: 0 | Q18: 39.09 | R18: 499 | S18: Apple Pay | T18: Google Shopping | U18: Refunded | V18: 2024-08-30 | W18: 499
A19: #ORD-10018 | B19: 2024-03-01 | C19: 08:52:46 | D19: Sophia Rodriguez | E19: sophia.rodriguez15@outlook.com | F19: +1-457-966-1832 | G19: Dallas | H19: TX | I19: United States | J19: Scented Soy Candle Set x1 | K19: Home & Living | L19: 1 | M19: 22.99 | N19: SAVE10 | O19: 2.3 | P19: 5.99 | Q19: 2.07 | R19: 28.75 | S19: PayPal | T19: Online Store | U19: Cancelled | W19: 0
A20: #ORD-10019 | B20: 2024-05-09 | C20: 12:58:20 | D20: Ethan Lewis | E20: ethan.lewis36@gmail.com | F20: +1-236-954-7049 | G20: Baltimore | H20: MD | I20: United States | J20: Essential Oil Diffuser x2 | Hiking Boots x1 | Running Shoes - Men's x1 | K20: Home & Living | L20: 3 | M20: 250.96 | N20: None | O20: 0 | P20: 0 | Q20: 15.06 | R20: 266.02 | S20: Credit Card | T20: Direct | U20: Fulfilled | V20: 2024-05-14 | W20: 0
A21: #ORD-10020 | B21: 2024-04-29 | C21: 17:10:33 | D21: Daniel Torres | E21: daniel.torres56@gmail.com | F21: +1-616-735-3532 | G21: Phoenix | H21: AZ | I21: United States | J21: Bamboo Sunglasses x2 | K21: Bags & Accessories | L21: 1 | M21: 49.98 | N21: None | O21: 0 | P21: 7.99 | Q21: 3.5 | R21: 61.47 | S21: PayPal | T21: Facebook | U21: Partially Fulfilled | V21: 2024-05-04 | W21: 0
A22: #ORD-10021 | B22: 2024-10-13 | C22: 01:16:42 | D22: Oliver Hernandez | E22: oliver.hernandez23@yahoo.com | F22: +1-671-458-6000 | G22: Louisville | H22: KY | I22: United States | J22: High-Waist Leggings x2 | Bamboo Sunglasses x2 | Multivitamin Daily Pack x1 | Anti-Aging Serum 1oz x2 | K22: Apparel | L22: 4 | M22: 255.93 | N22: None | O22: 0 | P22: 0 | Q22: 21.75 | R22: 277.68 | S22: Apple Pay | T22: Direct | U22: Fulfilled | V22: 2024-10-15 | W22: 0
A23: #ORD-10022 | B23: 2024-05-07 | C23: 11:37:23 | D23: Amelia Anderson | E23: amelia.anderson85@gmail.com | F23: +1-228-218-5279 | G23: New York | H23: NY | I23: United States | J23: USB-C Fast Charger 65W x3 | K23: Electronics | L23: 1 | M23: 89.97 | N23: SAVE10 | O23: 9 | P23: 0 | Q23: 6.48 | R23: 87.45 | S23: PayPal | T23: Online Store | U23: Refunded | V23: 2024-05-10 | W23: 87.45
A24: #ORD-10023 | B24: 2024-06-17 | C24: 18:25:40 | D24: Logan Hill | E24: logan.hill5@gmail.com | F24: +1-201-632-9821 | G24: Dallas | H24: TX | I24: United States | J24: High-Waist Leggings x1 | K24: Apparel | L24: 1 | M24: 42.99 | N24: LOYALTY5 | O24: 2.15 | P24: 4.99 | Q24: 3.47 | R24: 49.3 | S24: Apple Pay | T24: Online Store | U24: Fulfilled | V24: 2024-06-21 | W24: 0
A25: #ORD-10024 | B25: 2024-08-30 | C25: 00:13:45 | D25: Charlotte White | E25: charlotte.white9@outlook.com | F25: +1-330-296-7888 | G25: Columbus | H25: OH | I25: United States | J25: Canvas Backpack 25L x1 | K25: Bags & Accessories | L25: 1 | M25: 54.99 | N25: SAVE10 | O25: 5.5 | P25: 7.99 | Q25: 4.95 | R25: 62.43 | S25: Debit Card | T25: Instagram | U25: Fulfilled | V25: 2024-09-04 | W25: 0
A26: #ORD-10025 | B26: 2024-07-31 | C26: 19:08:41 | D26: Elizabeth Lopez | E26: elizabeth.lopez73@gmail.com | F26: +1-490-627-6491 | G26: Nashville | H26: TN | I26: United States | J26: Yoga Mat Premium x2 | Running Shoes - Women's x1 | Multivitamin Daily Pack x1 | K26: Sports & Fitness | L26: 3 | M26: 159.96 | N26: SUMMER20 | O26: 31.99 | P26: 0 | Q26: 10.88 | R26: 138.85 | S26: PayPal | T26: Instagram | U26: Fulfilled | V26: 2024-08-01 | W26: 0
A27: #ORD-10026 | B27: 2024-03-18 | C27: 08:01:31 | D27: Ethan Thomas | E27: ethan.thomas40@gmail.com | F27: +1-706-509-4997 | G27: El Paso | H27: TX | I27: United States | J27: Portable Bluetooth Speaker x1 | K27: Electronics | L27: 1 | M27: 49.99 | N27: SUMMER20 | O27: 10 | P27: 4.99 | Q27: 3.4 | R27: 48.38 | S27: Debit Card | T27: Facebook | U27: Fulfilled | V27: 2024-03-22 | W27: 0
A28: #ORD-10027 | B28: 2024-10-29 | C28: 07:24:14 | D28: James Smith | E28: james.smith97@outlook.com | F28: +1-336-920-8612 | G28: Albuquerque | H28: NM | I28: United States | J28: Running Shoes - Men's x2 | K28: Footwear | L28: 1 | M28: 149.98 | N28: FLASH25 | O28: 37.49 | P28: 0 | Q28: 9.56 | R28: 122.05 | S28: Credit Card | T28: Online Store | U28: Fulfilled | V28: 2024-11-02 | W28: 0
A29: #ORD-10028 | B29: 2024-08-25 | C29: 22:20:00 | D29: Owen Torres | E29: owen.torres41@outlook.com | F29: +1-696-741-4919 | G29: Nashville | H29: TN | I29: United States | J29: Leather Wallet Slim x2 | Air Fryer 5.8Qt x1 | Multivitamin Daily Pack x2 | K29: Bags & Accessories | L29: 3 | M29: 179.95 | N29: SUMMER20 | O29: 35.99 | P29: 0 | Q29: 12.24 | R29: 156.2 | S29: Credit Card | T29: Online Store | U29: Fulfilled | V29: 2024-08-30 | W29: 0
A30: #ORD-10029 | B30: 2024-04-15 | C30: 12:34:06 | D30: Elijah Robinson | E30: elijah.robinson92@gmail.com | F30: +1-624-517-6421 | G30: Chicago | H30: IL | I30: United States | J30: Leather Wallet Slim x1 | K30: Bags & Accessories | L30: 1 | M30: 29.99 | N30: None | O30: 0 | P30: 5.99 | Q30: 2.1 | R30: 38.08 | S30: Debit Card | T30: Online Store | U30: Fulfilled | V30: 2024-04-16 | W30: 0
A31: #ORD-10030 | B31: 2024-06-12 | C31: 04:01:17 | D31: Grace Walker | E31: grace.walker8@gmail.com | F31: +1-629-651-9947 | G31: Columbus | H31: OH | I31: United States | J31: Classic Fit Polo Shirt x1 | K31: Apparel | L31: 1 | M31: 34.99 | N31: None | O31: 0 | P31: 9.99 | Q31: 2.97 | R31: 47.95 | S31: Credit Card | T31: Online Store | U31: Unfulfilled | W31: 0
A32: #ORD-10031 | B32: 2024-07-07 | C32: 14:30:41 | D32: Victoria Anderson | E32: victoria.anderson29@gmail.com | F32: +1-603-706-1444 | G32: Indianapolis | H32: IN | I32: United States | J32: Resistance Band Set x1 | K32: Sports & Fitness | L32: 1 | M32: 24.99 | N32: WELCOME15 | O32: 3.75 | P32: 5.99 | Q32: 1.81 | R32: 29.04 | S32: Google Pay | T32: Referral | U32: Refunded | V32: 2024-07-08 | W32: 29.04
A33: #ORD-10032 | B33: 2024-04-11 | C33: 00:49:57 | D33: Ethan Lewis | E33: ethan.lewis60@gmail.com | F33: +1-681-119-9837 | G33: Phoenix | H33: AZ | I33: United States | J33: Running Shoes - Women's x1 | K33: Footwear | L33: 1 | M33: 69.99 | N33: SAVE10 | O33: 7 | P33: 9.99 | Q33: 5.04 | R33: 78.02 | S33: Shop Pay | T33: Email Campaign | U33: Fulfilled | V33: 2024-04-12 | W33: 0
A34: #ORD-10033 | B34: 2024-09-10 | C34: 02:47:37 | D34: Noah Thompson | E34: noah.thompson84@gmail.com | F34: +1-885-217-4571 | G34: San Diego | H34: CA | I34: United States | J34: Wireless Noise-Cancelling Headphones x3 | K34: Electronics | L34: 1 | M34: 269.97 | N34: None | O34: 0 | P34: 0 | Q34: 16.2 | R34: 286.17 | S34: PayPal | T34: Online Store | U34: Cancelled | W34: 0
A35: #ORD-10034 | B35: 2024-08-23 | C35: 19:57:24 | D35: Sebastian Taylor | E35: sebastian.taylor48@gmail.com | F35: +1-913-891-5941 | G35: Memphis | H35: TN | I35: United States | J35: Sunscreen SPF 50 Face x3 | Smart LED Desk Lamp x1 | Classic Fit Polo Shirt x1 | Denim Jacket x1 | Running Shoes - Men's x1 | K35: Beauty | L35: 5 | M35: 271.93 | N35: WELCOME15 | O35: 40.79 | P35: 0 | Q35: 19.65 | R35: 250.79 | S35: Google Pay | T35: Online Store | U35: Fulfilled | V35: 2024-08-24 | W35: 0
A36: #ORD-10035 | B36: 2024-06-15 | C36: 08:46:20 | D36: Victoria Davis | E36: victoria.davis73@yahoo.com | F36: +1-924-256-8135 | G36: Louisville | H36: KY | I36: United States | J36: USB-C Fast Charger 65W x1 | Air Fryer 5.8Qt x1 | K36: Electronics | L36: 2 | M36: 109.98 | N36: WELCOME15 | O36: 16.5 | P36: 0 | Q36: 7.95 | R36: 101.43 | S36: Credit Card | T36: TikTok Shop | U36: Cancelled | W36: 0
A37: #ORD-10036 | B37: 2024-10-27 | C37: 20:10:53 | D37: Logan Wright | E37: logan.wright35@outlook.com | F37: +1-783-724-7209 | G37: Oklahoma City | H37: OK | I37: United States | J37: Multivitamin Daily Pack x2 | Denim Jacket x1 | K37: Health & Nutrition | L37: 2 | M37: 104.97 | N37: None | O37: 0 | P37: 0 | Q37: 6.3 | R37: 111.27 | S37: Credit Card | T37: Instagram | U37: Cancelled | W37: 0
A38: #ORD-10037 | B38: 2024-03-23 | C38: 09:06:01 | D38: Muhammad Johnson | E38: muhammad.johnson42@gmail.com | F38: +1-287-347-7658 | G38: Indianapolis | H38: IN | I38: United States | J38: Hiking Boots x1 | K38: Footwear | L38: 1 | M38: 109.99 | N38: LOYALTY5 | O38: 5.5 | P38: 0 | Q38: 10.45 | R38: 114.94 | S38: Apple Pay | T38: Facebook | U38: Refunded | V38: 2024-03-25 | W38: 114.94
A39: #ORD-10038 | B39: 2024-07-09 | C39: 14:47:11 | D39: Michael Torres | E39: michael.torres31@outlook.com | F39: +1-766-643-6632 | G39: Memphis | H39: TN | I39: United States | J39: Wireless Noise-Cancelling Headphones x1 | K39: Electronics | L39: 1 | M39: 89.99 | N39: None | O39: 0 | P39: 0 | Q39: 7.65 | R39: 97.64 | S39: PayPal | T39: Online Store | U39: Partially Fulfilled | V39: 2024-07-13 | W39: 0
A40: #ORD-10039 | B40: 2024-04-07 | C40: 15:15:07 | D40: Jack Torres | E40: jack.torres46@yahoo.com | F40: +1-489-202-4180 | G40: Austin | H40: TX | I40: United States | J40: Men's Grooming Kit x1 | K40: Beauty | L40: 1 | M40: 35.99 | N40: None | O40: 0 | P40: 5.99 | Q40: 2.52 | R40: 44.5 | S40: Credit Card | T40: Instagram | U40: Refunded | V40: 2024-04-12 | W40: 44.5
...

Sheet Orders_Clean
A1: Order ID | B1: Order Date | C1: Order Time | D1: Customer Name | E1: Email | F1: Phone | G1: City | H1: State | I1: Country | J1: Line Items | K1: Primary Category | L1: Total Items | M1: Subtotal ($) | N1: Discount Code | O1: Discount Amount ($) | P1: Shipping ($) | Q1: Tax ($) | R1: Order Total ($) | S1: Payment Method | T1: Sales Channel | U1: Fulfillment Status | V1: Fulfillment Date | W1: Refund Amount ($) | X1: Month Name | Y1: Quarter | Z1: Net Revenue
A2: #ORD-10001 | B2: 2024-02-24 | C2: 04:35:15 | D2: Mason Johnson | E2: mason.johnson36@gmail.com | F2: +1-933-765-9928 | G2: Portland | H2: OR | I2: United States | J2: Anti-Aging Serum 1oz x1 | Men's Grooming Kit x1 | Leather Wallet Slim x1 | K2: Beauty | L2: 3 | M2: 115.97 | N2: None | O2: 0 | P2: 0 | Q2: 8.12 | R2: 124.09 | S2: Credit Card | T2: Facebook | U2: Refunded | V2: 2024-02-26 | W2: 124.09 | X2: =TEXT(B2,"MMMM") -> February | Y2: =IF(MONTH(B2)<=3,"Q1",IF(MONTH(B2)<=6,"Q2",IF(MONTH(B2)<=9,"Q3","Q4"))) -> Q1 | Z2: =M2-O2 -> 115.97
A3: #ORD-10002 | B3: 2024-12-03 | C3: 14:27:58 | D3: Sofia Anderson | E3: sofia.anderson76@gmail.com | F3: +1-294-489-2584 | G3: Charlotte | H3: NC | I3: United States | J3: High-Waist Leggings x1 | K3: Apparel | L3: 1 | M3: 42.99 | N3: WELCOME15 | O3: 6.45 | P3: 7.99 | Q3: 2.92 | R3: 47.45 | S3: Credit Card | T3: TikTok Shop | U3: Partially Fulfilled | V3: 2024-12-04 | W3: 0 | X3: =TEXT(B3,"MMMM") -> December | Y3: =IF(MONTH(B3)<=3,"Q1",IF(MONTH(B3)<=6,"Q2",IF(MONTH(B3)<=9,"Q3","Q4"))) -> Q4 | Z3: =M3-O3 -> 36.54
A4: #ORD-10003 | B4: 2024-07-27 | C4: 06:00:29 | D4: Emily Thompson | E4: emily.thompson34@outlook.com | F4: +1-246-777-4733 | G4: Nashville | H4: TN | I4: United States | J4: Bamboo Sunglasses x1 | K4: Bags & Accessories | L4: 1 | M4: 24.99 | N4: FLASH25 | O4: 6.25 | P4: 7.99 | Q4: 1.87 | R4: 28.6 | S4: PayPal | T4: Direct | U4: Fulfilled | V4: 2024-07-28 | W4: 0 | X4: =TEXT(B4,"MMMM") -> July | Y4: =IF(MONTH(B4)<=3,"Q1",IF(MONTH(B4)<=6,"Q2",IF(MONTH(B4)<=9,"Q3","Q4"))) -> Q3 | Z4: =M4-O4 -> 18.74
A5: #ORD-10004 | B5: 2024-06-25 | C5: 02:05:25 | D5: Evelyn Garcia | E5: evelyn.garcia30@yahoo.com | F5: +1-946-350-3677 | G5: Milwaukee | H5: WI | I5: United States | J5: Insulated Water Bottle 32oz x1 | Running Shoes - Men's x1 | K5: Sports & Fitness | L5: 2 | M5: 102.98 | N5: SAVE10 | O5: 10.3 | P5: 0 | Q5: 9.27 | R5: 101.95 | S5: Google Pay | T5: Facebook | U5: Fulfilled | V5: 2024-06-30 | W5: 0 | X5: =TEXT(B5,"MMMM") -> June | Y5: =IF(MONTH(B5)<=3,"Q1",IF(MONTH(B5)<=6,"Q2",IF(MONTH(B5)<=9,"Q3","Q4"))) -> Q2 | Z5: =M5-O5 -> 92.68
A6: #ORD-10005 | B6: 2024-05-05 | C6: 22:32:02 | D6: Sebastian Harris | E6: sebastian.harris82@yahoo.com | F6: +1-871-611-7482 | G6: Dallas | H6: TX | I6: United States | J6: Classic Fit Polo Shirt x2 | Portable Bluetooth Speaker x2 | Casual Sneakers x1 | K6: Apparel | L6: 3 | M6: 229.95 | N6: None | O6: 0 | P6: 0 | Q6: 16.1 | R6: 246.05 | S6: Google Pay | T6: Facebook | U6: Partially Fulfilled | V6: 2024-05-07 | W6: 0 | X6: =TEXT(B6,"MMMM") -> May | Y6: =IF(MONTH(B6)<=3,"Q1",IF(MONTH(B6)<=6,"Q2",IF(MONTH(B6)<=9,"Q3","Q4"))) -> Q2 | Z6: =M6-O6 -> 229.95
A7: #ORD-10006 | B7: 2024-08-06 | C7: 00:19:48 | D7: Sebastian Martinez | E7: sebastian.martinez18@gmail.com | F7: +1-293-873-1771 | G7: Dallas | H7: TX | I7: United States | J7: Men's Grooming Kit x1 | Linen Throw Blanket x1 | K7: Beauty | L7: 2 | M7: 75.98 | N7: SAVE10 | O7: 7.6 | P7: 0 | Q7: 4.79 | R7: 73.17 | S7: Afterpay | T7: Online Store | U7: Cancelled | W7: 0 | X7: =TEXT(B7,"MMMM") -> August | Y7: =IF(MONTH(B7)<=3,"Q1",IF(MONTH(B7)<=6,"Q2",IF(MONTH(B7)<=9,"Q3","Q4"))) -> Q3 | Z7: =M7-O7 -> 68.38
A8: #ORD-10007 | B8: 2024-01-25 | C8: 16:07:16 | D8: Mason Martinez | E8: mason.martinez21@yahoo.com | F8: +1-968-373-6573 | G8: Oklahoma City | H8: OK | I8: United States | J8: Scented Soy Candle Set x3 | K8: Home & Living | L8: 1 | M8: 68.97 | N8: FLASH25 | O8: 17.24 | P8: 7.99 | Q8: 4.66 | R8: 64.38 | S8: Apple Pay | T8: Online Store | U8: Fulfilled | V8: 2024-01-30 | W8: 0 | X8: =TEXT(B8,"MMMM") -> January | Y8: =IF(MONTH(B8)<=3,"Q1",IF(MONTH(B8)<=6,"Q2",IF(MONTH(B8)<=9,"Q3","Q4"))) -> Q1 | Z8: =M8-O8 -> 51.73
A9: #ORD-10008 | B9: 2024-10-07 | C9: 10:23:08 | D9: Mason Jackson | E9: mason.jackson21@gmail.com | F9: +1-752-897-9689 | G9: Columbus | H9: OH | I9: United States | J9: Hiking Boots x1 | Air Fryer 5.8Qt x2 | Classic Fit Polo Shirt x2 | K9: Footwear | L9: 3 | M9: 339.95 | N9: SAVE10 | O9: 33.99 | P9: 0 | Q9: 30.6 | R9: 336.56 | S9: Debit Card | T9: Online Store | U9: Partially Fulfilled | V9: 2024-10-09 | W9: 0 | X9: =TEXT(B9,"MMMM") -> October | Y9: =IF(MONTH(B9)<=3,"Q1",IF(MONTH(B9)<=6,"Q2",IF(MONTH(B9)<=9,"Q3","Q4"))) -> Q4 | Z9: =M9-O9 -> 305.96
A10: #ORD-10009 | B10: 2024-12-26 | C10: 19:49:36 | D10: Emma Flores | E10: emma.flores63@gmail.com | F10: +1-949-597-2133 | G10: Austin | H10: TX | I10: United States | J10: Denim Jacket x2 | K10: Apparel | L10: 1 | M10: 129.98 | N10: None | O10: 0 | P10: 0 | Q10: 7.8 | R10: 137.78 | S10: Credit Card | T10: Facebook | U10: Fulfilled | V10: 2024-12-27 | W10: 0 | X10: =TEXT(B10,"MMMM") -> December | Y10: =IF(MONTH(B10)<=3,"Q1",IF(MONTH(B10)<=6,"Q2",IF(MONTH(B10)<=9,"Q3","Q4"))) -> Q4 | Z10: =M10-O10 -> 129.98
A11: #ORD-10010 | B11: 2024-08-01 | C11: 12:32:27 | D11: Grace Rodriguez | E11: grace.rodriguez85@gmail.com | F11: +1-608-787-7118 | G11: Phoenix | H11: AZ | I11: United States | J11: Air Fryer 5.8Qt x2 | K11: Kitchen | L11: 1 | M11: 159.98 | N11: WELCOME15 | O11: 24 | P11: 0 | Q11: 9.52 | R11: 145.5 | S11: Google Pay | T11: Google Shopping | U11: Fulfilled | V11: 2024-08-04 | W11: 0 | X11: =TEXT(B11,"MMMM") -> August | Y11: =IF(MONTH(B11)<=3,"Q1",IF(MONTH(B11)<=6,"Q2",IF(MONTH(B11)<=9,"Q3","Q4"))) -> Q3 | Z11: =M11-O11 -> 135.98
A12: #ORD-10011 | B12: 2024-01-25 | C12: 20:45:52 | D12: Avery Wright | E12: avery.wright16@gmail.com | F12: +1-232-980-6413 | G12: Charlotte | H12: NC | I12: United States | J12: Linen Throw Blanket x1 | K12: Home & Living | L12: 1 | M12: 39.99 | N12: LOYALTY5 | O12: 2 | P12: 5.99 | Q12: 2.28 | R12: 46.26 | S12: Credit Card | T12: Facebook | U12: Fulfilled | V12: 2024-01-26 | W12: 0 | X12: =TEXT(B12,"MMMM") -> January | Y12: =IF(MONTH(B12)<=3,"Q1",IF(MONTH(B12)<=6,"Q2",IF(MONTH(B12)<=9,"Q3","Q4"))) -> Q1 | Z12: =M12-O12 -> 37.99
A13: #ORD-10012 | B13: 2024-02-21 | C13: 09:14:08 | D13: Ava King | E13: ava.king36@yahoo.com | F13: +1-620-578-1887 | G13: San Diego | H13: CA | I13: United States | J13: Leather Wallet Slim x1 | Linen Throw Blanket x1 | K13: Bags & Accessories | L13: 2 | M13: 69.98 | N13: SUMMER20 | O13: 14 | P13: 9.99 | Q13: 3.92 | R13: 69.89 | S13: Credit Card | T13: Facebook | U13: Partially Fulfilled | V13: 2024-02-25 | W13: 0 | X13: =TEXT(B13,"MMMM") -> February | Y13: =IF(MONTH(B13)<=3,"Q1",IF(MONTH(B13)<=6,"Q2",IF(MONTH(B13)<=9,"Q3","Q4"))) -> Q1 | Z13: =M13-O13 -> 55.98
A14: #ORD-10013 | B14: 2024-11-30 | C14: 15:22:12 | D14: Sophia Brown | E14: sophia.brown94@gmail.com | F14: +1-763-200-1828 | G14: Fort Worth | H14: TX | I14: United States | J14: Running Shoes - Women's x1 | K14: Footwear | L14: 1 | M14: 69.99 | N14: SUMMER20 | O14: 14 | P14: 5.99 | Q14: 4.76 | R14: 66.74 | S14: Credit Card | T14: Instagram | U14: Fulfilled | V14: 2024-12-04 | W14: 0 | X14: =TEXT(B14,"MMMM") -> November | Y14: =IF(MONTH(B14)<=3,"Q1",IF(MONTH(B14)<=6,"Q2",IF(MONTH(B14)<=9,"Q3","Q4"))) -> Q4 | Z14: =M14-O14 -> 55.99
A15: #ORD-10014 | B15: 2024-07-07 | C15: 14:30:12 | D15: Grace Smith | E15: grace.smith97@yahoo.com | F15: +1-492-533-8973 | G15: Chicago | H15: IL | I15: United States | J15: Canvas Backpack 25L x2 | Protein Powder Chocolate 2lb x1 | K15: Bags & Accessories | L15: 2 | M15: 154.97 | N15: None | O15: 0 | P15: 0 | Q15: 13.17 | R15: 168.14 | S15: Credit Card | T15: Email Campaign | U15: Cancelled | W15: 0 | X15: =TEXT(B15,"MMMM") -> July | Y15: =IF(MONTH(B15)<=3,"Q1",IF(MONTH(B15)<=6,"Q2",IF(MONTH(B15)<=9,"Q3","Q4"))) -> Q3 | Z15: =M15-O15 -> 154.97
A16: #ORD-10015 | B16: 2024-07-29 | C16: 13:37:32 | D16: James Gonzalez | E16: james.gonzalez28@outlook.com | F16: +1-282-971-4044 | G16: San Jose | H16: CA | I16: United States | J16: Resistance Band Set x1 | K16: Sports & Fitness | L16: 1 | M16: 24.99 | N16: LOYALTY5 | O16: 1.25 | P16: 9.99 | Q16: 2.14 | R16: 35.87 | S16: Google Pay | T16: Instagram | U16: Fulfilled | V16: 2024-08-03 | W16: 0 | X16: =TEXT(B16,"MMMM") -> July | Y16: =IF(MONTH(B16)<=3,"Q1",IF(MONTH(B16)<=6,"Q2",IF(MONTH(B16)<=9,"Q3","Q4"))) -> Q3 | Z16: =M16-O16 -> 23.74
A17: #ORD-10016 | B17: 2024-12-31 | C17: 16:18:43 | D17: Ava Flores | E17: ava.flores87@yahoo.com | F17: +1-334-787-5915 | G17: Chicago | H17: IL | I17: United States | J17: Casual Sneakers x1 | Linen Throw Blanket x1 | Scented Soy Candle Set x1 | Portable Bluetooth Speaker x1 | K17: Footwear | L17: 4 | M17: 172.96 | N17: SAVE10 | O17: 17.3 | P17: 0 | Q17: 10.9 | R17: 166.56 | S17: PayPal | T17: Online Store | U17: Fulfilled | V17: 2025-01-04 | W17: 0 | X17: =TEXT(B17,"MMMM") -> December | Y17: =IF(MONTH(B17)<=3,"Q1",IF(MONTH(B17)<=6,"Q2",IF(MONTH(B17)<=9,"Q3","Q4"))) -> Q4 | Z17: =M17-O17 -> 155.66
A18: #ORD-10017 | B18: 2024-08-29 | C18: 05:37:25 | D18: Sebastian Lee | E18: sebastian.lee97@yahoo.com | F18: +1-883-936-5905 | G18: Tucson | H18: AZ | I18: United States | J18: Smart LED Desk Lamp x1 | USB-C Fast Charger 65W x3 | Coffee Maker Programmable x2 | Running Shoes - Women's x2 | Air Fryer 5.8Qt x1 | K18: Electronics | L18: 5 | M18: 459.91 | N18: None | O18: 0 | P18: 0 | Q18: 39.09 | R18: 499 | S18: Apple Pay | T18: Google Shopping | U18: Refunded | V18: 2024-08-30 | W18: 499 | X18: =TEXT(B18,"MMMM") -> August | Y18: =IF(MONTH(B18)<=3,"Q1",IF(MONTH(B18)<=6,"Q2",IF(MONTH(B18)<=9,"Q3","Q4"))) -> Q3 | Z18: =M18-O18 -> 459.91
A19: #ORD-10018 | B19: 2024-03-01 | C19: 08:52:46 | D19: Sophia Rodriguez | E19: sophia.rodriguez15@outlook.com | F19: +1-457-966-1832 | G19: Dallas | H19: TX | I19: United States | J19: Scented Soy Candle Set x1 | K19: Home & Living | L19: 1 | M19: 22.99 | N19: SAVE10 | O19: 2.3 | P19: 5.99 | Q19: 2.07 | R19: 28.75 | S19: PayPal | T19: Online Store | U19: Cancelled | W19: 0 | X19: =TEXT(B19,"MMMM") -> March | Y19: =IF(MONTH(B19)<=3,"Q1",IF(MONTH(B19)<=6,"Q2",IF(MONTH(B19)<=9,"Q3","Q4"))) -> Q1 | Z19: =M19-O19 -> 20.69
A20: #ORD-10019 | B20: 2024-05-09 | C20: 12:58:20 | D20: Ethan Lewis | E20: ethan.lewis36@gmail.com | F20: +1-236-954-7049 | G20: Baltimore | H20: MD | I20: United States | J20: Essential Oil Diffuser x2 | Hiking Boots x1 | Running Shoes - Men's x1 | K20: Home & Living | L20: 3 | M20: 250.96 | N20: None | O20: 0 | P20: 0 | Q20: 15.06 | R20: 266.02 | S20: Credit Card | T20: Direct | U20: Fulfilled | V20: 2024-05-14 | W20: 0 | X20: =TEXT(B20,"MMMM") -> May | Y20: =IF(MONTH(B20)<=3,"Q1",IF(MONTH(B20)<=6,"Q2",IF(MONTH(B20)<=9,"Q3","Q4"))) -> Q2 | Z20: =M20-O20 -> 250.96
A21: #ORD-10020 | B21: 2024-04-29 | C21: 17:10:33 | D21: Daniel Torres | E21: daniel.torres56@gmail.com | F21: +1-616-735-3532 | G21: Phoenix | H21: AZ | I21: United States | J21: Bamboo Sunglasses x2 | K21: Bags & Accessories | L21: 1 | M21: 49.98 | N21: None | O21: 0 | P21: 7.99 | Q21: 3.5 | R21: 61.47 | S21: PayPal | T21: Facebook | U21: Partially Fulfilled | V21: 2024-05-04 | W21: 0 | X21: =TEXT(B21,"MMMM") -> April | Y21: =IF(MONTH(B21)<=3,"Q1",IF(MONTH(B21)<=6,"Q2",IF(MONTH(B21)<=9,"Q3","Q4"))) -> Q2 | Z21: =M21-O21 -> 49.98
A22: #ORD-10021 | B22: 2024-10-13 | C22: 01:16:42 | D22: Oliver Hernandez | E22: oliver.hernandez23@yahoo.com | F22: +1-671-458-6000 | G22: Louisville | H22: KY | I22: United States | J22: High-Waist Leggings x2 | Bamboo Sunglasses x2 | Multivitamin Daily Pack x1 | Anti-Aging Serum 1oz x2 | K22: Apparel | L22: 4 | M22: 255.93 | N22: None | O22: 0 | P22: 0 | Q22: 21.75 | R22: 277.68 | S22: Apple Pay | T22: Direct | U22: Fulfilled | V22: 2024-10-15 | W22: 0 | X22: =TEXT(B22,"MMMM") -> October | Y22: =IF(MONTH(B22)<=3,"Q1",IF(MONTH(B22)<=6,"Q2",IF(MONTH(B22)<=9,"Q3","Q4"))) -> Q4 | Z22: =M22-O22 -> 255.93
A23: #ORD-10022 | B23: 2024-05-07 | C23: 11:37:23 | D23: Amelia Anderson | E23: amelia.anderson85@gmail.com | F23: +1-228-218-5279 | G23: New York | H23: NY | I23: United States | J23: USB-C Fast Charger 65W x3 | K23: Electronics | L23: 1 | M23: 89.97 | N23: SAVE10 | O23: 9 | P23: 0 | Q23: 6.48 | R23: 87.45 | S23: PayPal | T23: Online Store | U23: Refunded | V23: 2024-05-10 | W23: 87.45 | X23: =TEXT(B23,"MMMM") -> May | Y23: =IF(MONTH(B23)<=3,"Q1",IF(MONTH(B23)<=6,"Q2",IF(MONTH(B23)<=9,"Q3","Q4"))) -> Q2 | Z23: =M23-O23 -> 80.97
A24: #ORD-10023 | B24: 2024-06-17 | C24: 18:25:40 | D24: Logan Hill | E24: logan.hill5@gmail.com | F24: +1-201-632-9821 | G24: Dallas | H24: TX | I24: United States | J24: High-Waist Leggings x1 | K24: Apparel | L24: 1 | M24: 42.99 | N24: LOYALTY5 | O24: 2.15 | P24: 4.99 | Q24: 3.47 | R24: 49.3 | S24: Apple Pay | T24: Online Store | U24: Fulfilled | V24: 2024-06-21 | W24: 0 | X24: =TEXT(B24,"MMMM") -> June | Y24: =IF(MONTH(B24)<=3,"Q1",IF(MONTH(B24)<=6,"Q2",IF(MONTH(B24)<=9,"Q3","Q4"))) -> Q2 | Z24: =M24-O24 -> 40.84
A25: #ORD-10024 | B25: 2024-08-30 | C25: 00:13:45 | D25: Charlotte White | E25: charlotte.white9@outlook.com | F25: +1-330-296-7888 | G25: Columbus | H25: OH | I25: United States | J25: Canvas Backpack 25L x1 | K25: Bags & Accessories | L25: 1 | M25: 54.99 | N25: SAVE10 | O25: 5.5 | P25: 7.99 | Q25: 4.95 | R25: 62.43 | S25: Debit Card | T25: Instagram | U25: Fulfilled | V25: 2024-09-04 | W25: 0 | X25: =TEXT(B25,"MMMM") -> August | Y25: =IF(MONTH(B25)<=3,"Q1",IF(MONTH(B25)<=6,"Q2",IF(MONTH(B25)<=9,"Q3","Q4"))) -> Q3 | Z25: =M25-O25 -> 49.49
A26: #ORD-10025 | B26: 2024-07-31 | C26: 19:08:41 | D26: Elizabeth Lopez | E26: elizabeth.lopez73@gmail.com | F26: +1-490-627-6491 | G26: Nashville | H26: TN | I26: United States | J26: Yoga Mat Premium x2 | Running Shoes - Women's x1 | Multivitamin Daily Pack x1 | K26: Sports & Fitness | L26: 3 | M26: 159.96 | N26: SUMMER20 | O26: 31.99 | P26: 0 | Q26: 10.88 | R26: 138.85 | S26: PayPal | T26: Instagram | U26: Fulfilled | V26: 2024-08-01 | W26: 0 | X26: =TEXT(B26,"MMMM") -> July | Y26: =IF(MONTH(B26)<=3,"Q1",IF(MONTH(B26)<=6,"Q2",IF(MONTH(B26)<=9,"Q3","Q4"))) -> Q3 | Z26: =M26-O26 -> 127.97
A27: #ORD-10026 | B27: 2024-03-18 | C27: 08:01:31 | D27: Ethan Thomas | E27: ethan.thomas40@gmail.com | F27: +1-706-509-4997 | G27: El Paso | H27: TX | I27: United States | J27: Portable Bluetooth Speaker x1 | K27: Electronics | L27: 1 | M27: 49.99 | N27: SUMMER20 | O27: 10 | P27: 4.99 | Q27: 3.4 | R27: 48.38 | S27: Debit Card | T27: Facebook | U27: Fulfilled | V27: 2024-03-22 | W27: 0 | X27: =TEXT(B27,"MMMM") -> March | Y27: =IF(MONTH(B27)<=3,"Q1",IF(MONTH(B27)<=6,"Q2",IF(MONTH(B27)<=9,"Q3","Q4"))) -> Q1 | Z27: =M27-O27 -> 39.99
A28: #ORD-10027 | B28: 2024-10-29 | C28: 07:24:14 | D28: James Smith | E28: james.smith97@outlook.com | F28: +1-336-920-8612 | G28: Albuquerque | H28: NM | I28: United States | J28: Running Shoes - Men's x2 | K28: Footwear | L28: 1 | M28: 149.98 | N28: FLASH25 | O28: 37.49 | P28: 0 | Q28: 9.56 | R28: 122.05 | S28: Credit Card | T28: Online Store | U28: Fulfilled | V28: 2024-11-02 | W28: 0 | X28: =TEXT(B28,"MMMM") -> October | Y28: =IF(MONTH(B28)<=3,"Q1",IF(MONTH(B28)<=6,"Q2",IF(MONTH(B28)<=9,"Q3","Q4"))) -> Q4 | Z28: =M28-O28 -> 112.49
A29: #ORD-10028 | B29: 2024-08-25 | C29: 22:20:00 | D29: Owen Torres | E29: owen.torres41@outlook.com | F29: +1-696-741-4919 | G29: Nashville | H29: TN | I29: United States | J29: Leather Wallet Slim x2 | Air Fryer 5.8Qt x1 | Multivitamin Daily Pack x2 | K29: Bags & Accessories | L29: 3 | M29: 179.95 | N29: SUMMER20 | O29: 35.99 | P29: 0 | Q29: 12.24 | R29: 156.2 | S29: Credit Card | T29: Online Store | U29: Fulfilled | V29: 2024-08-30 | W29: 0 | X29: =TEXT(B29,"MMMM") -> August | Y29: =IF(MONTH(B29)<=3,"Q1",IF(MONTH(B29)<=6,"Q2",IF(MONTH(B29)<=9,"Q3","Q4"))) -> Q3 | Z29: =M29-O29 -> 143.96
A30: #ORD-10029 | B30: 2024-04-15 | C30: 12:34:06 | D30: Elijah Robinson | E30: elijah.robinson92@gmail.com | F30: +1-624-517-6421 | G30: Chicago | H30: IL | I30: United States | J30: Leather Wallet Slim x1 | K30: Bags & Accessories | L30: 1 | M30: 29.99 | N30: None | O30: 0 | P30: 5.99 | Q30: 2.1 | R30: 38.08 | S30: Debit Card | T30: Online Store | U30: Fulfilled | V30: 2024-04-16 | W30: 0 | X30: =TEXT(B30,"MMMM") -> April | Y30: =IF(MONTH(B30)<=3,"Q1",IF(MONTH(B30)<=6,"Q2",IF(MONTH(B30)<=9,"Q3","Q4"))) -> Q2 | Z30: =M30-O30 -> 29.99
A31: #ORD-10030 | B31: 2024-06-12 | C31: 04:01:17 | D31: Grace Walker | E31: grace.walker8@gmail.com | F31: +1-629-651-9947 | G31: Columbus | H31: OH | I31: United States | J31: Classic Fit Polo Shirt x1 | K31: Apparel | L31: 1 | M31: 34.99 | N31: None | O31: 0 | P31: 9.99 | Q31: 2.97 | R31: 47.95 | S31: Credit Card | T31: Online Store | U31: Unfulfilled | W31: 0 | X31: =TEXT(B31,"MMMM") -> June | Y31: =IF(MONTH(B31)<=3,"Q1",IF(MONTH(B31)<=6,"Q2",IF(MONTH(B31)<=9,"Q3","Q4"))) -> Q2 | Z31: =M31-O31 -> 34.99
A32: #ORD-10031 | B32: 2024-07-07 | C32: 14:30:41 | D32: Victoria Anderson | E32: victoria.anderson29@gmail.com | F32: +1-603-706-1444 | G32: Indianapolis | H32: IN | I32: United States | J32: Resistance Band Set x1 | K32: Sports & Fitness | L32: 1 | M32: 24.99 | N32: WELCOME15 | O32: 3.75 | P32: 5.99 | Q32: 1.81 | R32: 29.04 | S32: Google Pay | T32: Referral | U32: Refunded | V32: 2024-07-08 | W32: 29.04 | X32: =TEXT(B32,"MMMM") -> July | Y32: =IF(MONTH(B32)<=3,"Q1",IF(MONTH(B32)<=6,"Q2",IF(MONTH(B32)<=9,"Q3","Q4"))) -> Q3 | Z32: =M32-O32 -> 21.24
A33: #ORD-10032 | B33: 2024-04-11 | C33: 00:49:57 | D33: Ethan Lewis | E33: ethan.lewis60@gmail.com | F33: +1-681-119-9837 | G33: Phoenix | H33: AZ | I33: United States | J33: Running Shoes - Women's x1 | K33: Footwear | L33: 1 | M33: 69.99 | N33: SAVE10 | O33: 7 | P33: 9.99 | Q33: 5.04 | R33: 78.02 | S33: Shop Pay | T33: Email Campaign | U33: Fulfilled | V33: 2024-04-12 | W33: 0 | X33: =TEXT(B33,"MMMM") -> April | Y33: =IF(MONTH(B33)<=3,"Q1",IF(MONTH(B33)<=6,"Q2",IF(MONTH(B33)<=9,"Q3","Q4"))) -> Q2 | Z33: =M33-O33 -> 62.99
A34: #ORD-10033 | B34: 2024-09-10 | C34: 02:47:37 | D34: Noah Thompson | E34: noah.thompson84@gmail.com | F34: +1-885-217-4571 | G34: San Diego | H34: CA | I34: United States | J34: Wireless Noise-Cancelling Headphones x3 | K34: Electronics | L34: 1 | M34: 269.97 | N34: None | O34: 0 | P34: 0 | Q34: 16.2 | R34: 286.17 | S34: PayPal | T34: Online Store | U34: Cancelled | W34: 0 | X34: =TEXT(B34,"MMMM") -> September | Y34: =IF(MONTH(B34)<=3,"Q1",IF(MONTH(B34)<=6,"Q2",IF(MONTH(B34)<=9,"Q3","Q4"))) -> Q3 | Z34: =M34-O34 -> 269.97
A35: #ORD-10034 | B35: 2024-08-23 | C35: 19:57:24 | D35: Sebastian Taylor | E35: sebastian.taylor48@gmail.com | F35: +1-913-891-5941 | G35: Memphis | H35: TN | I35: United States | J35: Sunscreen SPF 50 Face x3 | Smart LED Desk Lamp x1 | Classic Fit Polo Shirt x1 | Denim Jacket x1 | Running Shoes - Men's x1 | K35: Beauty | L35: 5 | M35: 271.93 | N35: WELCOME15 | O35: 40.79 | P35: 0 | Q35: 19.65 | R35: 250.79 | S35: Google Pay | T35: Online Store | U35: Fulfilled | V35: 2024-08-24 | W35: 0 | X35: =TEXT(B35,"MMMM") -> August | Y35: =IF(MONTH(B35)<=3,"Q1",IF(MONTH(B35)<=6,"Q2",IF(MONTH(B35)<=9,"Q3","Q4"))) -> Q3 | Z35: =M35-O35 -> 231.14
A36: #ORD-10035 | B36: 2024-06-15 | C36: 08:46:20 | D36: Victoria Davis | E36: victoria.davis73@yahoo.com | F36: +1-924-256-8135 | G36: Louisville | H36: KY | I36: United States | J36: USB-C Fast Charger 65W x1 | Air Fryer 5.8Qt x1 | K36: Electronics | L36: 2 | M36: 109.98 | N36: WELCOME15 | O36: 16.5 | P36: 0 | Q36: 7.95 | R36: 101.43 | S36: Credit Card | T36: TikTok Shop | U36: Cancelled | W36: 0 | X36: =TEXT(B36,"MMMM") -> June | Y36: =IF(MONTH(B36)<=3,"Q1",IF(MONTH(B36)<=6,"Q2",IF(MONTH(B36)<=9,"Q3","Q4"))) -> Q2 | Z36: =M36-O36 -> 93.48
A37: #ORD-10036 | B37: 2024-10-27 | C37: 20:10:53 | D37: Logan Wright | E37: logan.wright35@outlook.com | F37: +1-783-724-7209 | G37: Oklahoma City | H37: OK | I37: United States | J37: Multivitamin Daily Pack x2 | Denim Jacket x1 | K37: Health & Nutrition | L37: 2 | M37: 104.97 | N37: None | O37: 0 | P37: 0 | Q37: 6.3 | R37: 111.27 | S37: Credit Card | T37: Instagram | U37: Cancelled | W37: 0 | X37: =TEXT(B37,"MMMM") -> October | Y37: =IF(MONTH(B37)<=3,"Q1",IF(MONTH(B37)<=6,"Q2",IF(MONTH(B37)<=9,"Q3","Q4"))) -> Q4 | Z37: =M37-O37 -> 104.97
A38: #ORD-10037 | B38: 2024-03-23 | C38: 09:06:01 | D38: Muhammad Johnson | E38: muhammad.johnson42@gmail.com | F38: +1-287-347-7658 | G38: Indianapolis | H38: IN | I38: United States | J38: Hiking Boots x1 | K38: Footwear | L38: 1 | M38: 109.99 | N38: LOYALTY5 | O38: 5.5 | P38: 0 | Q38: 10.45 | R38: 114.94 | S38: Apple Pay | T38: Facebook | U38: Refunded | V38: 2024-03-25 | W38: 114.94 | X38: =TEXT(B38,"MMMM") -> March | Y38: =IF(MONTH(B38)<=3,"Q1",IF(MONTH(B38)<=6,"Q2",IF(MONTH(B38)<=9,"Q3","Q4"))) -> Q1 | Z38: =M38-O38 -> 104.49
A39: #ORD-10038 | B39: 2024-07-09 | C39: 14:47:11 | D39: Michael Torres | E39: michael.torres31@outlook.com | F39: +1-766-643-6632 | G39: Memphis | H39: TN | I39: United States | J39: Wireless Noise-Cancelling Headphones x1 | K39: Electronics | L39: 1 | M39: 89.99 | N39: None | O39: 0 | P39: 0 | Q39: 7.65 | R39: 97.64 | S39: PayPal | T39: Online Store | U39: Partially Fulfilled | V39: 2024-07-13 | W39: 0 | X39: =TEXT(B39,"MMMM") -> July | Y39: =IF(MONTH(B39)<=3,"Q1",IF(MONTH(B39)<=6,"Q2",IF(MONTH(B39)<=9,"Q3","Q4"))) -> Q3 | Z39: =M39-O39 -> 89.99
A40: #ORD-10039 | B40: 2024-04-07 | C40: 15:15:07 | D40: Jack Torres | E40: jack.torres46@yahoo.com | F40: +1-489-202-4180 | G40: Austin | H40: TX | I40: United States | J40: Men's Grooming Kit x1 | K40: Beauty | L40: 1 | M40: 35.99 | N40: None | O40: 0 | P40: 5.99 | Q40: 2.52 | R40: 44.5 | S40: Credit Card | T40: Instagram | U40: Refunded | V40: 2024-04-12 | W40: 44.5 | X40: =TEXT(B40,"MMMM") -> April | Y40: =IF(MONTH(B40)<=3,"Q1",IF(MONTH(B40)<=6,"Q2",IF(MONTH(B40)<=9,"Q3","Q4"))) -> Q2 | Z40: =M40-O40 -> 35.99
...

Sheet KPIs
B2: SHOPIFY STORE — KPI SUMMARY 2024 | H2: Month Number | I2: Monthly Revenue
B3: Total Orders | D3: =COUNTA('Raw Data'!A2:A1001) -> 1000 | H3: 1 | I3: {=SUMPRODUCT((MONTH(Orders_Clean!B2:B1001)=1)*Orders_Clean!R2:R1001)} -> 12015.35
B4: Total Revenue | D4: =SUM('Raw Data'!R2:R1001) -> 137929.05 | H4: 2 | I4: {=SUMPRODUCT((MONTH(Orders_Clean!B2:B1001)=2)*Orders_Clean!R2:R1001)} -> 11262.67
B5: Average Order Value | D5: =AVERAGE('Raw Data'!R2:R1001) -> 137.92905 | H5: 3 | I5: {=SUMPRODUCT((MONTH(Orders_Clean!B2:B1001)=3)*Orders_Clean!R2:R1001)} -> 11094.63
B6: Total Discounts Given | D6: =SUM('Raw Data'!O2:O1001) -> 11873.42 | H6: 4 | I6: {=SUMPRODUCT((MONTH(Orders_Clean!B2:B1001)=4)*Orders_Clean!R2:R1001)} -> 10162.84
B7: Total Refunds | D7: =SUM('Raw Data'!W2:W1001) -> 13886.31 | H7: 5 | I7: {=SUMPRODUCT((MONTH(Orders_Clean!B2:B1001)=5)*Orders_Clean!R2:R1001)} -> 11951.2
B8: Refund Rate | D8: =COUNTIF('Raw Data'!U2:U1001,"Refunded")/COUNTA('Raw Data'!A2:A1001) -> 0.1 | H8: 6 | I8: {=SUMPRODUCT((MONTH(Orders_Clean!B2:B1001)=6)*Orders_Clean!R2:R1001)} -> 9587.24
B9: Cancellation Rate | D9: =COUNTIF('Raw Data'!U2:U1001,"Cancelled")/COUNTA('Raw Data'!A2:A1001) -> 0.117 | H9: 7 | I9: {=SUMPRODUCT((MONTH(Orders_Clean!B2:B1001)=7)*Orders_Clean!R2:R1001)} -> 10833.23
B10: Best Revenue Month | D10: =TEXT(DATE(2024,MATCH(MAX(I2:I13),I2:I13,0),1),"MMMM") -> November | H10: 8 | I10: {=SUMPRODUCT((MONTH(Orders_Clean!B2:B1001)=8)*Orders_Clean!R2:R1001)} -> 11882.41
B11: Free Shipping Orders | D11: =COUNTIF('Raw Data'!P2:P1001,0) -> 637 | H11: 9 | I11: {=SUMPRODUCT((MONTH(Orders_Clean!B2:B1001)=9)*Orders_Clean!R2:R1001)} -> 11557.71
H12: 10 | I12: {=SUMPRODUCT((MONTH(Orders_Clean!B2:B1001)=10)*Orders_Clean!R2:R1001)} -> 15430.39
H13: 11 | I13: {=SUMPRODUCT((MONTH(Orders_Clean!B2:B1001)=11)*Orders_Clean!R2:R1001)} -> 12119.81
H14: 12 | I14: {=SUMPRODUCT((MONTH(Orders_Clean!B2:B1001)=12)*Orders_Clean!R2:R1001)} -> 10031.57

Sheet Revenue by Month
A3: Months | B3: Sum of Revenue ($)
A4: January | B4: 12015.35
A5: February | B5: 11262.67
A6: March | B6: 11094.63
A7: April | B7: 10162.84
A8: May | B8: 11951.2
A9: June | B9: 9587.24
A10: July | B10: 10833.23
A11: August | B11: 11882.41
A12: September | B12: 11557.71
A13: October | B13: 15430.39
A14: November | B14: 12119.81
A15: December | B15: 10031.57
A16: (blank)
A17: Grand Total | B17: 137929.05

Sheet Orders by Sales
A3: Sales Channel | B3: Count of Orders | C3: Sum of Total Orders
A4: Direct | B4: 62 | C4: 8795.36
A5: Email Campaign | B5: 70 | C5: 9891.8
A6: Facebook | B6: 159 | C6: 22135.54
A7: Google Shopping | B7: 91 | C7: 13660.34
A8: Instagram | B8: 141 | C8: 18093.53
A9: Online Store | B9: 397 | C9: 54025.51
A10: Referral | B10: 32 | C10: 4946.67
A11: TikTok Shop | B11: 48 | C11: 6380.3
A12: (blank)
A13: Grand Total | B13: 1000 | C13: 137929.05

Sheet Fulfillment status breakdown
A3: Fulfillment Status | B3: Count of Orders | C3: % of Orders
A4: Cancelled | B4: 117 | C4: =B4/$B$9 -> 0.117
A5: Fulfilled | B5: 560 | C5: =B5/$B$9 -> 0.56
A6: Partially Fulfilled | B6: 115 | C6: =B6/$B$9 -> 0.115
A7: Refunded | B7: 100 | C7: =B7/$B$9 -> 0.1
A8: Unfulfilled | B8: 108 | C8: =B8/$B$9 -> 0.108
A9: Grand Total | B9: 1000 | C9: =B9/$B$9 -> 1

Sheet Revenue by Product
A3: Primary Category | B3: Sum Total of Orders
A4: Electronics | B4: 29497.7
A5: Footwear | B5: 20735.62
A6: Kitchen | B6: 18619.95
A7: Bags & Accessories | B7: 13417.3
A8: Beauty | B8: 12370.7
A9: Apparel | B9: 12082
A10: Home & Living | B10: 10360.24
A11: Sports & Fitness | B11: 10277.13
A12: Health & Nutrition | B12: 7646.82
A13: Food & Beverage | B13: 2921.59
A14: Grand Total | B14: 137929.05

Sheet Payment Method analysis
A3: Payment Method | B3: Average Total of Orders
A4: Afterpay | B4: 140.64429
A5: Apple Pay | B5: 139.37583
A6: Credit Card | B6: 135.61138
A7: Debit Card | B7: 133.9624
A8: Google Pay | B8: 128.45033
A9: Klarna | B9: 147.79774
A10: PayPal | B10: 150.2501
A11: Shop Pay | B11: 128.61853
A12: Grand Total | B12: 137.92905

Sheet Dashboard
A1: SHOPIFY STORE - EXECUTIVE SALES DASHBOARD - FY2024
B3: TOTAL REVENUE | F3: TOTAL ORDERS | J3: AVG ORDER VALUE | N3: REFUND RATE
B5: =SUM('Raw Data'!R2:R1001) -> 137929.05 | F5: =COUNTA('Raw Data'!A2:A1001) -> 1000 | J5: =AVERAGE('Raw Data'!R2:R1001) -> 137.92905 | N5: =COUNTIF('Raw Data'!U2:U1001,"Refunded")/COUNTA('Raw Data'!A2:A1001) -> 0.1

Sheet Insights
A1: SHOPIFY STORE - 2024 PERFORMANCE INSIGHTS
A3: EXECUTIVE SUMMARY
A5: The store prcessed 1,000 orders in 2024 generating $137929.05 in total revenue with an average order value of $137.9. The strongest sales channel was Online Store and peak revenue occurred in Q4 2024.Key areas for improvement include the refund rate and cancellation rate which together account for 11.70% of all orders processed during the year.
A7: # | B7: FINDING | C7: SUPPORTING DATA | D7: TREND
A8: 1 | B8: Q4 was the strongest quarter driving the highest revenue of the year | C8: {=SUMPRODUCT((Orders_Clean!Y2:Y1001="Q4")*Orders_Clean!R2:R1001)} -> 37581.77
A9: 2 | B9: Online Store is the top sales channel by both order volume and revenue | C9: =COUNTIF(Orders_Clean!T2:T1001,"Online Store") -> 397
A10: 3 | B10: More than half of all orders qualified for free shipping (order above $75) | C10: =COUNTIF(Orders_Clean!P2:P1001,0) -> 637
A11: 4 | B11: Discount codes were used in a significant portion of all orders | C11: =COUNTIF(Orders_Clean!N2:N1001,"<>None")/COUNTA(Orders_Clean!A2:A1001) -> 0.623
A12: 5 | B12: Refunded orders have the highest average order value among all statuses | C12: =AVERAGEIF(Orders_Clean!U2:U1001,"Refunded",Orders_Clean!R2:R1001) -> 138.8631
A13: 6 | B13: Electronics and Kitchen are the top two revenue generating categories | C13: =SUMIF(Orders_Clean!K2:K1001,"Electronics",Orders_Clean!R2:R1001) -> 29497.7
A14: 7 | B14: Shop Pay users show above average order values compared to other methods | C14: =AVERAGEIF(Orders_Clean!S2:S1001,"Shop Pay",Orders_Clean!R2:R1001) -> 128.61853
